Workbook

Sheet Phân công
A1: MSSV | B1: Họ tên SV | C1: Lớp | D1: GVHD | E1: GVPB | F1: CTHĐ | G1: TVHĐ | H1: TKHĐ | I1: Thời gian | J1: Phòng | K1: Hội đồng
A2: K224141715 | B2: Phạm Thụy Phương Dung | C2: K22414E | D2: PGS. TS Lê Đức Quang Tú | E2: TS Nguyễn Thanh Liêm | F2: TS Nguyễn Thanh Liêm | G2: TS Nguyễn Trung Hiếu | H2: ThS Ngô Phú Thanh | I2: 8h00 sáng thứ năm ngày 05/3/2026 | J2: B1.501 | K2: 01
A3: K224141738 | B3: Vũ Ngọc Thuỷ Tiên | C3: K22414E | D3: PGS. TS Lê Đức Quang Tú | E3: TS Nguyễn Trung Hiếu | F3: TS Nguyễn Thanh Liêm | G3: TS Nguyễn Trung Hiếu | H3: ThS Ngô Phú Thanh | I3: 8h00 sáng thứ năm ngày 05/3/2026 | J3: B1.501 | K3: 01
A4: K224141652 | B4: Lê Phúc Chí | C4: K22414 | D4: PGS. TS Nguyễn Anh Phong | E4: TS Nguyễn Trung Hiếu | F4: TS Nguyễn Thanh Liêm | G4: TS Nguyễn Trung Hiếu | H4: ThS Ngô Phú Thanh | I4: 8h00 sáng thứ năm ngày 05/3/2026 | J4: B1.501 | K4: 01
A5: K224141654 | B5: Đào Mỹ Duyên | C5: K22414 | D5: PGS. TS Nguyễn Anh Phong | E5: ThS Ngô Phú Thanh | F5: TS Nguyễn Thanh Liêm | G5: TS Nguyễn Trung Hiếu | H5: ThS Ngô Phú Thanh | I5: 8h00 sáng thứ năm ngày 05/3/2026 | J5: B1.501 | K5: 01
A6: K224141658 | B6: Đào Ngọc Hà | C6: K22414 | D6: PGS. TS Nguyễn Anh Phong | E6: TS Nguyễn Thanh Liêm | F6: TS Nguyễn Thanh Liêm | G6: TS Nguyễn Trung Hiếu | H6: ThS Ngô Phú Thanh | I6: 8h00 sáng thứ năm ngày 05/3/2026 | J6: B1.501 | K6: 01
A7: K224040570 | B7: Nguyễn Yến Linh | C7: K22404E | D7: PGS. TS Lê Đức Quang Tú
A8: K224040583 | B8: Tô Như Quỳnh | C8: K22404E | D8: PGS. TS Lê Đức Quang Tú
A9: K224040584 | B9: Trần Ngọc Lan Thanh | C9: K22404E | D9: PGS. TS Lê Đức Quang Tú
A10: K224040585 | B10: Ngô Nguyễn Quỳnh Thơ | C10: K22404E | D10: PGS. TS Lê Đức Quang Tú
A11: K224141659 | B11: Mai Thị Thanh Hà | C11: K22414 | D11: PGS. TS Nguyễn Anh Phong | E11: TS Nguyễn Trung Hiếu | F11: TS Nguyễn Thanh Liêm | G11: TS Nguyễn Trung Hiếu | H11: ThS Ngô Phú Thanh | I11: 8h00 sáng thứ năm ngày 05/3/2026 | J11: B1.501 | K11: 01
A12: K224141667 | B12: Lê Thị Hương | C12: K22414 | D12: PGS. TS Nguyễn Anh Phong | E12: ThS Ngô Phú Thanh | F12: TS Nguyễn Thanh Liêm | G12: TS Nguyễn Trung Hiếu | H12: ThS Ngô Phú Thanh | I12: 8h00 sáng thứ năm ngày 05/3/2026 | J12: B1.501 | K12: 01
A13: K224141714 | B13: Lê Danh Bách | C13: K22414E | D13: PGS. TS Phạm Thị Thanh Xuân | E13: TS Nguyễn Thanh Liêm | F13: TS Nguyễn Thanh Liêm | G13: TS Nguyễn Trung Hiếu | H13: ThS Ngô Phú Thanh | I13: 8h00 sáng thứ năm ngày 05/3/2026 | J13: B1.501 | K13: 01
A14: K224141730 | B14: Đoàn Tuấn Nghĩa | C14: K22414E | D14: PGS. TS Phạm Thị Thanh Xuân | E14: TS Nguyễn Trung Hiếu | F14: TS Nguyễn Thanh Liêm | G14: TS Nguyễn Trung Hiếu | H14: ThS Ngô Phú Thanh | I14: 8h00 sáng thứ năm ngày 05/3/2026 | J14: B1.501 | K14: 01
A15: K224141733 | B15: Bùi Đặng Quỳnh Như | C15: K22414E | D15: PGS. TS Phạm Thị Thanh Xuân | E15: ThS Ngô Phú Thanh | F15: TS Nguyễn Thanh Liêm | G15: TS Nguyễn Trung Hiếu | H15: ThS Ngô Phú Thanh | I15: 8h00 sáng thứ năm ngày 05/3/2026 | J15: B1.501 | K15: 01
A16: K224141711 | B16: Lê Phú An | C16: K22414E | D16: TS Nguyễn Thôn Dã | E16: TS Nguyễn Thanh Liêm | F16: TS Nguyễn Thanh Liêm | G16: TS Nguyễn Trung Hiếu | H16: ThS Ngô Phú Thanh | I16: 8h00 sáng thứ năm ngày 05/3/2026 | J16: B1.501 | K16: 01
A17: K224141655 | B17: Lê Thị Mỹ Duyên | C17: K22414 | D17: ThS Ngô Phú Thanh | E17: TS Nguyễn Thôn Dã | F17: PGS. TS Lê Đức Quang Tú | G17: TS Nguyễn Thôn Dã | H17: TS Võ Thị Ngọc Trinh | I17: 8h00 sáng thứ năm ngày 05/3/2026 | J17: B1.502 | K17: 02
A18: K224141668 | B18: Phan Vũ Đình Khang | C18: K22414 | D18: ThS Ngô Phú Thanh | E18: TS Võ Thị Ngọc Trinh | F18: PGS. TS Lê Đức Quang Tú | G18: TS Nguyễn Thôn Dã | H18: TS Võ Thị Ngọc Trinh | I18: 8h00 sáng thứ năm ngày 05/3/2026 | J18: B1.502 | K18: 02
A19: K224141703 | B19: Thông Thị Quế Trân | C19: K22414 | D19: ThS Ngô Phú Thanh | E19: PGS. TS Lê Đức Quang Tú | F19: PGS. TS Lê Đức Quang Tú | G19: TS Nguyễn Thôn Dã | H19: TS Võ Thị Ngọc Trinh | I19: 8h00 sáng thứ năm ngày 05/3/2026 | J19: B1.502 | K19: 02
A20: K224141649 | B20: Trần Lê Quang An | C20: K22414 | D20: ThS Ngô Phú Thanh | E20: TS Nguyễn Thôn Dã | F20: PGS. TS Lê Đức Quang Tú | G20: TS Nguyễn Thôn Dã | H20: TS Võ Thị Ngọc Trinh | I20: 8h00 sáng thứ năm ngày 05/3/2026 | J20: B1.502 | K20: 02
A21: K224141657 | B21: Bùi Thị Ngọc Hà | C21: K22414 | D21: ThS Ngô Phú Thanh | E21: TS Võ Thị Ngọc Trinh | F21: PGS. TS Lê Đức Quang Tú | G21: TS Nguyễn Thôn Dã | H21: TS Võ Thị Ngọc Trinh | I21: 8h00 sáng thứ năm ngày 05/3/2026 | J21: B1.502 | K21: 02
A22: K224141717 | B22: Trần Đức Duy | C22: K22414E | D22: ThS Phạm Chí Khoa | E22: PGS. TS Lê Đức Quang Tú | F22: PGS. TS Lê Đức Quang Tú | G22: TS Nguyễn Thôn Dã | H22: TS Võ Thị Ngọc Trinh | I22: 8h00 sáng thứ năm ngày 05/3/2026 | J22: B1.502 | K22: 02
... A34: K224141713 | B34: Nguyễn Thương Kỳ Anh | C34: K22414E | D34: TS Nguyễn Trung Hiếu | E34: ThS Phạm Chí Khoa | F34: PGS. TS Phạm Thị Thanh Xuân | G34: ThS Phan Huy Tâm | H34: ThS Phạm Chí Khoa | I34: 8h00 sáng thứ năm ngày 05/3/2026 | J34: B1.503 | K34: 03
A35: K224040575 | B35: Phan Quang Minh | C35: K22404E | D35: PGS. TS Nguyễn Thị Ánh Như
A36: K224040586 | B36: Đặng Hoài Minh Thư | C36: K22404E | D36: PGS. TS Nguyễn Thị Ánh Như
A37: K224040591 | B37: Nguyễn Hà Trâm | C37: K22404E | D37: PGS. TS Nguyễn Thị Ánh Như
A38: K224040593 | B38: Phạm Văn Trọng | C38: K22404E | D38: PGS. TS Nguyễn Thị Ánh Như
A39: K224040594 | B39: Nguyễn Thành Trung | C39: K22404E | D39: PGS. TS Nguyễn Thị Ánh Như
A40: K224040595 | B40: Lê Nguyễn Thanh Trúc | C40: K22404E | D40: PGS. TS Nguyễn Thị Ánh Như
A41: K224141726 | B41: Dương Thị Thuỳ Linh | C41: K22414E | D41: TS Nguyễn Trung Hiếu | E41: PGS. TS Phạm Thị Thanh Xuân | F41: PGS. TS Phạm Thị Thanh Xuân | G41: ThS Phan Huy Tâm | H41: ThS Phạm Chí Khoa | I41: 8h00 sáng thứ năm ngày 05/3/2026 | J41: B1.503 | K41: 03
A42: K224141744 | B42: Lâm Thanh Vi | C42: K22414E | D42: TS Nguyễn Trung Hiếu | E42: ThS Phan Huy Tâm | F42: PGS. TS Phạm Thị Thanh Xuân | G42: ThS Phan Huy Tâm | H42: ThS Phạm Chí Khoa | I42: 8h00 sáng thứ năm ngày 05/3/2026 | J42: B1.503 | K42: 03
A43: K224141710 | B43: Lê Hoàng Phi Yến | C43: K22414 | D43: TS Võ Thị Ngọc Trinh | E43: ThS Phạm Chí Khoa | F43: PGS. TS Phạm Thị Thanh Xuân | G43: ThS Phan Huy Tâm | H43: ThS Phạm Chí Khoa | I43: 8h00 sáng thứ năm ngày 05/3/2026 | J43: B1.503 | K43: 03
A44: K224141716 | B44: Nguyễn Quang Duy | C44: K22414E | D44: TS Võ Thị Ngọc Trinh | E44: PGS. TS Phạm Thị Thanh Xuân | F44: PGS. TS Phạm Thị Thanh Xuân | G44: ThS Phan Huy Tâm | H44: ThS Phạm Chí Khoa | I44: 8h00 sáng thứ năm ngày 05/3/2026 | J44: B1.503 | K44: 03
A45: K224141673 | B45: Phạm Gia Linh | C45: K22414 | D45: PGS. TS Nguyễn Anh Phong | E45: TS Nguyễn Thanh Liêm | F45: TS Nguyễn Thanh Liêm | G45: TS Nguyễn Trung Hiếu | H45: ThS Ngô Phú Thanh | I45: 13h00 chiều thứ năm ngày 05/3/2026 | J45: B1.501 | K45: 04
A46: K224141677 | B46: Nguyễn Bùi Kim Ngân | C46: K22414 | D46: PGS. TS Nguyễn Anh Phong | E46: TS Nguyễn Trung Hiếu | F46: TS Nguyễn Thanh Liêm | G46: TS Nguyễn Trung Hiếu | H46: ThS Ngô Phú Thanh | I46: 13h00 chiều thứ năm ngày 05/3/2026 | J46: B1.501 | K46: 04
A47: K224040550 | B47: Nguyễn Thị Hải Tiên | C47: K22404 | D47: PGS. TS Phạm Thị Thanh Xuân
A48: K224040553 | B48: Lý Bảo Trân | C48: K22404 | D48: PGS. TS Phạm Thị Thanh Xuân
A49: K224040555 | B49: Nguyễn Trần Ngọc Trúc | C49: K22404 | D49: PGS. TS Phạm Thị Thanh Xuân
A50: K224040580 | B50: Vũ Thị Hồng Phúc | C50: K22404E | D50: PGS. TS Phạm Thị Thanh Xuân
A51: K224040581 | B51: Đoàn Hà Phương | C51: K22404E | D51: PGS. TS Phạm Thị Thanh Xuân
...

Sheet Sheet5
A1: MSSV | B1: Họ tên | C1: Ngày sinh | D1: Mobile Phone | E1: Email | F1: CTĐT | G1: Tên CTĐT | H1: Tình trạng | I1: Điều kiện CCNN | J1: Số TC tích lũy | K1: ĐTBCTL | L1: Xếp loại tích lũy
A2: K224020262 | B2: Nguyễn Đặng Vi Bân | C2: 15/02/2004 | D2: 767551049 | E2: banndv224022c@st.uel.edu.vn | F2: 404C | G2: Tài chính - Ngân hàng Chất lượng cao | H2: Còn học | I2: Đạt CCNN | J2: 124 | K2: 8.6 | L2: Giỏi
A3: K224040464 | B3: Phạm Vũ Tú Anh | C3: 38175 | D3: 858485811 | E3: anhpvt22404a@st.uel.edu.vn | F3: 412 | G3: Ngân hàng | H3: Còn học | I3: Đạt CCNN | J3: 124 | K3: 8.51 | L3: Giỏi
A4: K224040465 | B4: Trương Thị Nhã Ái | C4: 16/04/2004 | D4: 943865399 | E4: aittn22404a@st.uel.edu.vn | F4: 404 | G4: Tài chính - Ngân hàng | H4: Còn học | I4: Đạt CCNN | J4: 128 | K4: 8.51 | L4: Giỏi
A5: K224040466 | B5: Nguyễn Đình Thiên Ân | C5: 16/07/2004 | D5: 816109429 | E5: anndt22404a@st.uel.edu.vn | F5: 412 | G5: Ngân hàng | H5: Còn học | I5: Đạt CCNN | J5: 121 | K5: 7.4 | L5: Khá
A6: K224040467 | B6: Tô Gia Bảo | C6: 38332 | D6: 911789147 | E6: baotg22404a@st.uel.edu.vn | F6: 412 | G6: Ngân hàng | H6: Còn học | I6: Đạt CCNN | J6: 124 | K6: 7.24 | L6: Khá
A7: K224040468 | B7: Phạm Mai Chi | C7: 38201 | D7: 862209865 | E7: chipm22404a@st.uel.edu.vn | F7: 412 | G7: Ngân hàng | H7: Còn học | I7: Đạt CCNN | J7: 124 | K7: 7.36 | L7: Khá
A8: K224040469 | B8: Nguyễn Thị Thúy Diễm | C8: 15/10/2004 | D8: 949271804 | E8: diemntt22404a@st.uel.edu.vn | F8: 412 | G8: Ngân hàng | H8: Còn học | I8: Đạt CCNN | J8: 124 | K8: 7.99 | L8: Khá
A9: K224040470 | B9: Đào Hồ Trúc Giang | C9: 38027 | E9: giangdht22404a@st.uel.edu.vn | F9: 404 | G9: Tài chính - Ngân hàng | H9: Còn học | I9: Đạt CCNN | J9: 122 | K9: 8.25 | L9: Giỏi
A10: K224040471 | B10: Nguyễn Thị Thu Hà | C10: 24/01/2004 | D10: 835484304 | E10: hantt22404a@st.uel.edu.vn | F10: 404 | G10: Tài chính - Ngân hàng | H10: Còn học | I10: Đạt CCNN | J10: 126 | K10: 8.46 | L10: Giỏi
A11: K224040472 | B11: Võ Thị Hồng Hạnh | C11: 25/12/2004 | D11: 794563867 | E11: hanhvth22404a@st.uel.edu.vn | F11: 404 | G11: Tài chính - Ngân hàng | H11: Còn học | I11: Đạt CCNN | J11: 126 | K11: 8.09 | L11: Giỏi
A12: K224040473 | B12: Trần Thị Thu Hằng | C12: 37842 | D12: 363954822 | E12: hangttt22404a@st.uel.edu.vn | F12: 404 | G12: Tài chính - Ngân hàng | H12: Còn học | I12: Đạt CCNN | J12: 126 | K12: 8.05 | L12: Giỏi
A13: K224040474 | B13: Phan Thanh Thanh Hiền | C13: 38328 | E13: hienptt22404a@st.uel.edu.vn | F13: 404 | G13: Tài chính - Ngân hàng | H13: Còn học | I13: Đạt CCNN | J13: 126 | K13: 7.96 | L13: Khá
A14: K224040475 | B14: Lý Nhật Huy | C14: 36861 | E14: huyln22404a@st.uel.edu.vn | F14: 404 | G14: Tài chính - Ngân hàng | H14: Còn học | I14: Đạt CCNN | J14: 126 | K14: 7.69 | L14: Khá
A15: K224040476 | B15: Lê Huỳnh Khánh Huyền | C15: 30/04/2004 | D15: 901669495 | E15: huyenlhk22404a@st.uel.edu.vn | F15: 404 | G15: Tài chính - Ngân hàng | H15: Còn học | I15: Đạt CCNN | J15: 126 | K15: 8.29 | L15: Giỏi
A16: K224040477 | B16: Nguyễn Trần Vũ Hùng | C16: 31/07/2004 | D16: 867050070 | E16: hungntv22404a@st.uel.edu.vn | F16: 404 | G16: Tài chính - Ngân hàng | H16: Còn học | I16: Đạt CCNN | J16: 126 | K16: 8.49 | L16: Giỏi
A17: K224040478 | B17: Nguyễn Tuấn Kiệt | C17: 38267 | D17: 394377963 | E17: kietnt22404a@st.uel.edu.vn | F17: 412 | G17: Ngân hàng | H17: Còn học | I17: Đạt CCNN | J17: 124 | K17: 7.06 | L17: Khá
A18: K224040479 | B18: Nguyễn Thị Hạnh Linh | C18: 27/11/2004 | D18: 787300568 | E18: linhnth22404a@st.uel.edu.vn | F18: 404 | G18: Tài chính - Ngân hàng | H18: Còn học | I18: Đạt CCNN | J18: 126 | K18: 8.12 | L18: Giỏi
A19: K224040480 | B19: Hồ Thị Bích Ly | C19: 13/08/2004 | E19: lyhtb22404a@st.uel.edu.vn | F19: 404 | G19: Tài chính - Ngân hàng | H19: Còn học | I19: Đạt CCNN | J19: 124 | K19: 8.41 | L19: Giỏi
A20: K224040481 | B20: Vũ Nhật Minh | C20: 38087 | D20: 768658405 | E20: minhvn22404a@st.uel.edu.vn | F20: 404 | G20: Tài chính - Ngân hàng | H20: Còn học | I20: Đạt CCNN | J20: 122 | K20: 8.98 | L20: Giỏi
A21: K224040482 | B21: Dương Công Nam | C21: 29/05/2003 | D21: 931969308 | E21: namdc22404a@st.uel.edu.vn | F21: 412 | G21: Ngân hàng | H21: Còn học | I21: Đạt CCNN | J21: 124 | K21: 7.41 | L21: Khá
A22: K224040483 | B22: Phan Thúy Ngân | C22: 38111 | D22: 839257952 | E22: nganpt22404a@st.uel.edu.vn | F22: 404 | G22: Tài chính - Ngân hàng | H22: Còn học | I22: Đạt CCNN | J22: 126 | K22: 8.39 | L22: Giỏi
A23: K224040484 | B23: Trần Huỳnh Phương Nghi | C23: 26/10/2004 | D23: 918276265 | E23: nghithp22404a@st.uel.edu.vn | F23: 404 | G23: Tài chính - Ngân hàng | H23: Còn học | I23: Đạt CCNN | J23: 126 | K23: 8.61 | L23: Giỏi
A24: K224040485 | B24: Triệu Hoàng Kim Nguyên | C24: 15/06/2004 | D24: 589103713 | E24: nguyenthk22404a@st.uel.edu.vn | F24: 412 | G24: Ngân hàng | H24: Còn học | I24: Chưa đạt CCNN | J24: 124 | K24: 7.51 | L24: Khá
A25: K224040486 | B25: Hoàng Thị Huệ Nhi | C25: 25/12/2004 | D25: 852955447 | E25: nhihth22404a@st.uel.edu.vn | F25: 404 | G25: Tài chính - Ngân hàng | H25: Còn học | I25: Đạt CCNN | J25: 130 | K25: 7.72 | L25: Khá
A26: K224040487 | B26: Nghiêm Thùy Yến Nhi | C26: 16/05/2004 | D26: 867573703 | E26: nhinty22404a@st.uel.edu.vn | F26: 412 | G26: Ngân hàng | H26: Còn học | I26: Đạt CCNN | J26: 124 | K26: 7.62 | L26: Khá
A27: K224040488 | B27: Nguyễn Thị Thanh Nhung | C27: 28/04/2004 | E27: nhungntt22404a@st.uel.edu.vn | F27: 404 | G27: Tài chính - Ngân hàng | H27: Còn học | I27: Đạt CCNN | J27: 126 | K27: 8.64 | L27: Giỏi
A28: K224040489 | B28: Thiều Thị Ngọc Oanh | C28: 30/12/2004 | D28: 933979864 | E28: oanhttn22404a@st.uel.edu.vn | F28: 412 | G28: Ngân hàng | H28: Còn học | I28: Đạt CCNN | J28: 124 | K28: 8.18 | L28: Giỏi
A29: K224040490 | B29: Nguyễn Ngọc Châu Phương | C29: 38085 | E29: phuongnnc22404a@st.uel.edu.vn | F29: 412 | G29: Ngân hàng | H29: Còn học | I29: Đạt CCNN | J29: 124 | K29: 7.86 | L29: Khá
A30: K224040491 | B30: Nguyễn Duy Phúc | C30: 38271 | E30: phucnd22404a@st.uel.edu.vn | F30: 412 | G30: Ngân hàng | H30: Còn học | I30: Đạt CCNN | J30: 124 | K30: 8.09 | L30: Giỏi
A31: K224040492 | B31: Lê Mạnh Quân | C31: 17/10/2004 | D31: 397569520 | E31: quanlm22404a@st.uel.edu.vn | F31: 404 | G31: Tài chính - Ngân hàng | H31: Còn học | I31: Đạt CCNN | J31: 126 | K31: 8.3 | L31: Giỏi
A32: K224040493 | B32: Nguyễn Ngọc Quỳnh | C32: 20/08/2004 | D32: 949866704 | E32: quynhnn22404a@st.uel.edu.vn | F32: 404 | G32: Tài chính - Ngân hàng | H32: Còn học | I32: Đạt CCNN | J32: 122 | K32: 7.84 | L32: Khá
A33: K224040494 | B33: Huỳnh Thị Thanh Tâm | C33: 28/01/2003 | D33: 345998367 | E33: tamhtt22404a@st.uel.edu.vn | F33: 412 | G33: Ngân hàng | H33: Còn học | I33: Đạt CCNN | J33: 124 | K33: 7.51 | L33: Khá
A34: K224040495 | B34: Hà Huy Tân | C34: 15/08/2004 | D34: 902156726 | E34: tanhh22404a@st.uel.edu.vn | F34: 412 | G34: Ngân hàng | H34: Còn học | I34: Đạt CCNN | J34: 124 | K34: 7.45 | L34: Khá
A35: K224040496 | B35: Mai Công Thanh | C35: 38295 | D35: 372539123 | E35: thanhmc22404a@st.uel.edu.vn | F35: 404 | G35: Tài chính - Ngân hàng | H35: Còn học | I35: Đạt CCNN | J35: 122 | K35: 8.21 | L35: Giỏi
A36: K224040496 | B36: Mai Công Thanh | C36: 38295 | D36: 372539123 | E36: thanhmc22404a@st.uel.edu.vn | F36: 406 | G36: Hệ thống thông tin quản lý | H36: Còn học | I36: Đạt CCNN | J36: 120 | K36: 8.27 | L36: Giỏi
A37: K224040497 | B37: Phan Như Thành | C37: 21/04/2004 | E37: thanhpn22404a@st.uel.edu.vn | F37: 412 | G37: Ngân hàng | H37: Còn học | I37: Chưa đạt CCNN | J37: 121 | K37: 6.92 | L37: Trung bình khá
A38: K224040498 | B38: Lê Hưng Thịnh | C38: 38265 | D38: 912161571 | E38: thinhlh22404a@st.uel.edu.vn | F38: 404 | G38: Tài chính - Ngân hàng | H38: Còn học | I38: Đạt CCNN | J38: 126 | K38: 7.77 | L38: Khá
A39: K224040499 | B39: Bùi Anh Thư | C39: 20/08/2004 | E39: thuba22404a@st.uel.edu.vn | F39: 404 | G39: Tài chính - Ngân hàng | H39: Còn học | I39: Đạt CCNN | J39: 126 | K39: 7.93 | L39: Khá
A40: K224040500 | B40: Nguyễn Thị Thương | C40: 38058 | D40: 357501455 | E40: thuongnt22404a@st.uel.edu.vn | F40: 404 | G40: Tài chính - Ngân hàng | H40: Còn học | I40: Đạt CCNN | J40: 126 | K40: 7.81 | L40: Khá
...

Sheet Số bài mỗi hội đồng
B1: Hội đồng | C1: Số lượng
A2: 414, 414C | B2: 1 | C2: =COUNTIF('Phân công'!#REF!,B2) -> #REF!
A3: 414, 414C | B3: 2 | C3: =COUNTIF('Phân công'!#REF!,B3) -> #REF!
A4: 414, 414C | B4: 3 | C4: =COUNTIF('Phân công'!#REF!,B4) -> #REF!
A5: 414, 414C | B5: 4 | C5: =COUNTIF('Phân công'!#REF!,B5) -> #REF!
A6: 414, 414C | B6: 5 | C6: =COUNTIF('Phân công'!#REF!,B6) -> #REF!
A7: 414, 414C | B7: 6 | C7: =COUNTIF('Phân công'!#REF!,B7) -> #REF!
A8: 414, 414C | B8: 7 | C8: =COUNTIF('Phân công'!#REF!,B8) -> #REF!
A9: 414, 414C | B9: 8 | C9: =COUNTIF('Phân công'!#REF!,B9) -> #REF!
A10: 404C | B10: 9 | C10: =COUNTIF('Phân công'!#REF!,B10) -> #REF!
A11: Đại trà | B11: 10 | C11: =COUNTIF('Phân công'!#REF!,B11) -> #REF!
A12: CA | B12: 11 | C12: =COUNTIF('Phân công'!#REF!,B12) -> #REF!
A13: CA | B13: 12 | C13: =COUNTIF('Phân công'!#REF!,B13) -> #REF!

Sheet Thù lao
B1: BCTT | J1: HD KLTN | R1: PB KLTN | Z1: CT KLTN | AH1: Ủy viên KLTN | AP1: Thư ký KLTN | AX1: HĐ | BF1: BCCĐTT | BG1: PB KLTN | BH1: CT KLTN | BI1: UV KLTN | BJ1: Tky KLTN | BK1: HD KLTN | BL1: Thù lao HD BCTT & HD KLTN (VNĐ) | BM1: Thù lao Hội đồng (VNĐ) | BN1: Thù lao HD và HĐ KLTN (VNĐ) | BO1: Tổng cộng (VNĐ)
A2: Họ và tên GV/Đơn giá | B2: 404 | C2: 412 | D2: 414 | E2: 404C | F2: 404C | G2: 414C | H2: 414C | I2: CA | J2: 404 | K2: 412 | L2: 414 | M2: 404C | N2: 404C | O2: 414C | P2: 414C | Q2: CA | R2: 404 | S2: 412 | T2: 414 | U2: 404C | V2: 404C | W2: 414C | X2: 414C | Y2: CA | Z2: 404 | AA2: 412 | AB2: 414 | AC2: 404C | AD2: 404C | AE2: 414C | AF2: 414C | AG2: CA | AH2: 404 | AI2: 412 | AJ2: 414 | AK2: 404C | AL2: 404C | AM2: 414C | AN2: 414C | AO2: CA | AP2: 404 | AQ2: 412 | AR2: 414 | AS2: 404C | AT2: 404C | AU2: 414C | AV2: 414C | AW2: CA | AX2: 404 | AY2: 412 | AZ2: 414 | BA2: 404C | BB2: 404C | BC2: 414C | BD2: 414C | BE2: CA | BF2: 420000 | BG2: 240000 | BH2: 150000 | BI2: 150000 | BJ2: 150000 | BK2: 720000
A3: Hệ số thù lao | B3: 1 | C3: 1 | D3: 1 | E3: 1.5 | F3: 3 | G3: 1.5 | H3: 3 | I3: 3 | J3: 1 | K3: 1 | L3: 1 | M3: 1.5 | N3: 3 | O3: 1.5 | P3: 3 | Q3: 3 | R3: 1 | S3: 1 | T3: 1 | U3: 1.5 | V3: 3 | W3: 1.5 | X3: 3 | Y3: 3 | Z3: 1 | AA3: 1 | AB3: 1 | AC3: 1.5 | AD3: 3 | AE3: 1.5 | AF3: 3 | AG3: 3 | AH3: 1 | AI3: 1 | AJ3: 1 | AK3: 1.5 | AL3: 3 | AM3: 1.5 | AN3: 3 | AO3: 3 | AP3: 1 | AQ3: 1 | AR3: 1 | AS3: 1.5 | AT3: 3 | AU3: 1.5 | AV3: 3 | AW3: 3 | AX3: 1 | AY3: 1 | AZ3: 1 | BA3: 1.5 | BB3: 3 | BC3: 1.5 | BD3: 3 | BE3: 3
A4: TS Nguyễn Hoàng Anh | B4: =SUMPRODUCT(('Phân công'!$D$2:$D$259=$A4)*('Phân công'!#REF!="X")*(RIGHT('Phân công'!$C$2:$C$259,3)="404")) -> #REF! | C4: =SUMPRODUCT(('Phân công'!$D$2:$D$259=$A4)*('Phân công'!#REF!="X")*(RIGHT('Phân công'!$C$2:$C$259,3)="412")) -> #REF! | D4: =SUMPRODUCT(('Phân công'!$D$2:$D$259=$A4)*('Phân công'!#REF!="X")*(RIGHT('Phân công'!$C$2:$C$259,3)="414")) -> #REF! | E4: =SUMPRODUCT(('Phân công'!$D$2:$D$259=$A4)*('Phân công'!#REF!="X")*(RIGHT('Phân công'!$C$2:$C$259,4)="404C")*('Phân công'!#REF!="Tiếng Việt")) -> #REF! | F4: =SUMPRODUCT(('Phân công'!$D$2:$D$259=$A4)*('Phân công'!#REF!="X")*(RIGHT('Phân công'!$C$2:$C$259,4)="404C")*('Phân công'!#REF!="Tiếng Anh")) -> #REF! | G4: =SUMPRODUCT(('Phân công'!$D$2:$D$259=$A4)*('Phân công'!#REF!="X")*(RIGHT('Phân công'!$C$2:$C$259,4)="414C")*('Phân công'!#REF!="Tiếng Việt")) -> #REF! | H4: =SUMPRODUCT(('Phân công'!$D$2:$D$259=$A4)*('Phân công'!#REF!="X")*(RIGHT('Phân công'!$C$2:$C$259,4)="414C")*('Phân công'!#REF!="Tiếng Anh")) -> #REF! | I4: =SUMPRODUCT(('Phân công'!$D$2:$D$259=$A4)*('Phân công'!#REF!="X")*(RIGHT('Phân công'!$C$2:$C$259,5)="404CA")) -> #REF! | J4: =SUMPRODUCT(('Phân công'!$D$2:$D$259=$A4)*('Phân công'!#REF!="X")*(RIGHT('Phân công'!$C$2:$C$259,3)="404")) -> #REF! | K4: =SUMPRODUCT(('Phân công'!$D$2:$D$259=$A4)*('Phân công'!#REF!="X")*(RIGHT('Phân công'!$C$2:$C$259,3)="412")) -> #REF! | L4: =SUMPRODUCT(('Phân công'!$D$2:$D$259=$A4)*('Phân công'!#REF!="X")*(RIGHT('Phân công'!$C$2:$C$259,3)="414")) -> #REF! | M4: =SUMPRODUCT(('Phân công'!$D$2:$D$259=$A4)*('Phân công'!#REF!="X")*(RIGHT('Phân công'!$C$2:$C$259,3)="04C")*('Phân công'!#REF!="Tiếng Việt")) -> #REF! | N4: =SUMPRODUCT(('Phân công'!$D$2:$D$259=$A4)*('Phân công'!#REF!="X")*(RIGHT('Phân công'!$C$2:$C$259,3)="04C")*('Phân công'!#REF!="Tiếng Anh")) -> #REF! | O4: =SUMPRODUCT(('Phân công'!$D$2:$D$259=$A4)*('Phân công'!#REF!="X")*(RIGHT('Phân công'!$C$2:$C$259,3)="14C")*('Phân công'!#REF!="Tiếng Việt")) -> #REF! | P4: =SUMPRODUCT(('Phân công'!$D$2:$D$259=$A4)*('Phân công'!#REF!="X")*(RIGHT('Phân công'!$C$2:$C$259,3)="14C")*('Phân công'!#REF!="Tiếng Anh")) -> #REF! | Q4: =SUMPRODUCT(('Phân công'!$D$2:$D$259=$A4)*('Phân công'!#REF!="X")*(RIGHT('Phân công'!$C$2:$C$259,3)="4CA")) -> #REF! | R4: =SUMPRODUCT(('Phân công'!#REF!='Thù lao'!A4)*(RIGHT('Phân công'!$C$2:$C$259,3)="404")) -> #REF! | S4: =SUMPRODUCT(('Phân công'!#REF!='Thù lao'!A4)*(RIGHT('Phân công'!$C$2:$C$259,3)="412")) -> #REF! | T4: =SUMPRODUCT(('Phân công'!#REF!='Thù lao'!A4)*(RIGHT('Phân công'!$C$2:$C$259,3)="414")) -> #REF! | U4: =SUMPRODUCT(('Phân công'!#REF!='Thù lao'!A4)*(RIGHT('Phân công'!$C$2:$C$259,3)="04C")*('Phân công'!#REF!="Tiếng Việt")) -> #REF! | V4: =SUMPRODUCT(('Phân công'!#REF!='Thù lao'!A4)*(RIGHT('Phân công'!$C$2:$C$259,3)="04C")*('Phân công'!#REF!="Tiếng Anh")) -> #REF! | W4: =SUMPRODUCT(('Phân công'!#REF!='Thù lao'!A4)*(RIGHT('Phân công'!$C$2:$C$259,3)="14C")*('Phân công'!#REF!="Tiếng Việt")) -> #REF! | X4: =SUMPRODUCT(('Phân công'!#REF!='Thù lao'!A4)*(RIGHT('Phân công'!$C$2:$C$259,3)="14C")*('Phân công'!#REF!="Tiếng Anh")) -> #REF! | Y4: =SUMPRODUCT(('Phân công'!#REF!='Thù lao'!A4)*(RIGHT('Phân công'!$C$2:$C$259,3)="4CA")) -> #REF! | Z4: =SUMPRODUCT(('Phân công'!#REF!='Thù lao'!A4)*(RIGHT('Phân công'!$C$2:$C$259,3)="404")) -> #REF! | AA4: =SUMPRODUCT(('Phân công'!#REF!='Thù lao'!A4)*(RIGHT('Phân công'!$C$2:$C$259,3)="412")) -> #REF! | AB4: =SUMPRODUCT(('Phân công'!#REF!='Thù lao'!A4)*(RIGHT('Phân công'!$C$2:$C$259,3)="414")) -> #REF! | AC4: =SUMPRODUCT(('Phân công'!#REF!='Thù lao'!A4)*(RIGHT('Phân công'!$C$2:$C$259,3)="04C")*('Phân công'!#REF!="Tiếng Việt")) -> #REF! | AD4: =SUMPRODUCT(('Phân công'!#REF!='Thù lao'!A4)*(RIGHT('Phân công'!$C$2:$C$259,3)="04C")*('Phân công'!#REF!="Tiếng Anh")) -> #REF! | AE4: =SUMPRODUCT(('Phân công'!#REF!='Thù lao'!A4)*(RIGHT('Phân công'!$C$2:$C$259,3)="14C")*('Phân công'!#REF!="Tiếng Việt")) -> #REF! | AF4: =SUMPRODUCT(('Phân công'!#REF!='Thù lao'!A4)*(RIGHT('Phân công'!$C$2:$C$259,3)="14C")*('Phân công'!#REF!="Tiếng Anh")) -> #REF! | AG4: =SUMPRODUCT(('Phân công'!#REF!='Thù lao'!A4)*(RIGHT('Phân công'!$C$2:$C$259,3)="4CA")) -> #REF! | AH4: =SUMPRODUCT(('Phân công'!#REF!='Thù lao'!A4)*(RIGHT('Phân công'!$C$2:$C$259,3)="404")) -> #REF! | AI4: =SUMPRODUCT(('Phân công'!#REF!='Thù lao'!A4)*(RIGHT('Phân công'!$C$2:$C$259,3)="412")) -> #REF! | AJ4: =SUMPRODUCT(('Phân công'!#REF!='Thù lao'!A4)*(RIGHT('Phân công'!$C$2:$C$259,3)="414")) -> #REF! | AK4: =SUMPRODUCT(('Phân công'!#REF!='Thù lao'!A4)*(RIGHT('Phân công'!$C$2:$C$259,3)="04C")*('Phân công'!#REF!="Tiếng Việt")) -> #REF! | AL4: =SUMPRODUCT(('Phân công'!#REF!='Thù lao'!A4)*(RIGHT('Phân công'!$C$2:$C$259,3)="04C")*('Phân công'!#REF!="Tiếng Anh")) -> #REF! | AM4: =SUMPRODUCT(('Phân công'!#REF!='Thù lao'!A4)*(RIGHT('Phân công'!$C$2:$C$259,3)="14C")*('Phân công'!#REF!="Tiếng Việt")) -> #REF! | AN4: =SUMPRODUCT(('Phân công'!#REF!='Thù lao'!A4)*(RIGHT('Phân công'!$C$2:$C$259,3)="14C")*('Phân công'!#REF!="Tiếng Anh")) -> #REF! | AO4: =SUMPRODUCT(('Phân công'!#REF!='Thù lao'!A4)*(RIGHT('Phân công'!$C$2:$C$259,3)="4CA")) -> #REF! | AP4: =SUMPRODUCT(('Phân công'!#REF!='Thù lao'!A4)*(RIGHT('Phân công'!$C$2:$C$259,3)="404")) -> #REF! | AQ4: =SUMPRODUCT(('Phân công'!#REF!='Thù lao'!A4)*(RIGHT('Phân công'!$C$2:$C$259,3)="412")) -> #REF! | AR4: =SUMPRODUCT(('Phân công'!#REF!='Thù lao'!A4)*(RIGHT('Phân công'!$C$2:$C$259,3)="414")) -> #REF! | AS4: =SUMPRODUCT(('Phân công'!#REF!='Thù lao'!A4)*(RIGHT('Phân công'!$C$2:$C$259,3)="04C")*('Phân công'!#REF!="Tiếng Việt")) -> #REF! | AT4: =SUMPRODUCT(('Phân công'!#REF!='Thù lao'!A4)*(RIGHT('Phân công'!$C$2:$C$259,3)="04C")*('Phân công'!#REF!="Tiếng Anh")) -> #REF! | AU4: =SUMPRODUCT(('Phân công'!#REF!='Thù lao'!A4)*(RIGHT('Phân công'!$C$2:$C$259,3)="14C")*('Phân công'!#REF!="Tiếng Việt")) -> #REF! | AV4: =SUMPRODUCT(('Phân công'!#REF!='Thù lao'!A4)*(RIGHT('Phân công'!$C$2:$C$259,3)="14C")*('Phân công'!#REF!="Tiếng Anh")) -> #REF! | AW4: =SUMPRODUCT(('Phân công'!#REF!='Thù lao'!A4)*(RIGHT('Phân công'!$C$2:$C$259,3)="4CA")) -> #REF! | AX4: =AP4+AH4+Z4+R4 -> #REF! | AY4: =AQ4+AI4+AA4+S4 -> #REF! | AZ4: =AR4+AJ4+AB4+T4 -> #REF! | BA4: =AS4+AK4+AC4+U4 -> #REF! | BB4: =AT4+AL4+AD4+V4 -> #REF! | BC4: =AU4+AM4+AE4+W4 -> #REF! | BD4: =AV4+AN4+AF4+X4 -> #REF! | BE4: =AW4+AO4+AG4+Y4 -> #REF! | BF4: =SUMPRODUCT((B4:I4),($B$3:$I$3))*$BF$2 -> #REF! | BG4: =SUMPRODUCT(R4:Y4,$R$3:$Y$3)*$BG$2 -> #REF! | BH4: =SUMPRODUCT(Z4:AG4,$Z$3:$AG$3)*$BH$2 -> #REF! | BI4: =SUMPRODUCT(AH4:AO4,$AH$3:$AO$3)*$BI$2 -> #REF! | BJ4: =SUMPRODUCT(AP4:AW4,$AP$3:$AW$3)*$BJ$2 -> #REF! | BK4: =SUMPRODUCT((J4:Q4),($J$3:$Q$3))*$BK$2 -> #REF! | BL4: =BF4+BK4 -> #REF! | BM4: =SUM(BG4:BJ4) -> #REF! | BN4: =BM4+BK4 -> #REF! | BO4: =BL4+BM4 -> #REF!
A5: ThS Nguyễn Thị Hai Hằng | B5: =SUMPRODUCT(('Phân công'!$D$2:$D$259=$A5)*('Phân công'!#REF!="X")*(RIGHT('Phân công'!$C$2:$C$259,3)="404")) -> #REF! | C5: =SUMPRODUCT(('Phân công'!$D$2:$D$259=$A5)*('Phân công'!#REF!="X")*(RIGHT('Phân công'!$C$2:$C$259,3)="412")) -> #REF! | D5: =SUMPRODUCT(('Phân công'!$D$2:$D$259=$A5)*('Phân công'!#REF!="X")*(RIGHT('Phân công'!$C$2:$C$259,3)="414")) -> #REF! | E5: =SUMPRODUCT(('Phân công'!$D$2:$D$259=$A5)*('Phân công'!#REF!="X")*(RIGHT('Phân công'!$C$2:$C$259,4)="404C")*('Phân công'!#REF!="Tiếng Việt")) -> #REF! | F5: =SUMPRODUCT(('Phân công'!$D$2:$D$259=$A5)*('Phân công'!#REF!="X")*(RIGHT('Phân công'!$C$2:$C$259,4)="404C")*('Phân công'!#REF!="Tiếng Anh")) -> #REF! | G5: =SUMPRODUCT(('Phân công'!$D$2:$D$259=$A5)*('Phân công'!#REF!="X")*(RIGHT('Phân công'!$C$2:$C$259,4)="414C")*('Phân công'!#REF!="Tiếng Việt")) -> #REF! | H5: =SUMPRODUCT(('Phân công'!$D$2:$D$259=$A5)*('Phân công'!#REF!="X")*(RIGHT('Phân công'!$C$2:$C$259,4)="414C")*('Phân công'!#REF!="Tiếng Anh")) -> #REF! | I5: =SUMPRODUCT(('Phân công'!$D$2:$D$259=$A5)*('Phân công'!#REF!="X")*(RIGHT('Phân công'!$C$2:$C$259,5)="404CA")) -> #REF! | J5: =SUMPRODUCT(('Phân công'!$D$2:$D$259=$A5)*('Phân công'!#REF!="X")*(RIGHT('Phân công'!$C$2:$C$259,3)="404")) -> #REF! | K5: =SUMPRODUCT(('Phân công'!$D$2:$D$259=$A5)*('Phân công'!#REF!="X")*(RIGHT('Phân công'!$C$2:$C$259,3)="412")) -> #REF! | L5: =SUMPRODUCT(('Phân công'!$D$2:$D$259=$A5)*('Phân công'!#REF!="X")*(RIGHT('Phân công'!$C$2:$C$259,3)="414")) -> #REF! | M5: =SUMPRODUCT(('Phân công'!$D$2:$D$259=$A5)*('Phân công'!#REF!="X")*(RIGHT('Phân công'!$C$2:$C$259,3)="04C")*('Phân công'!#REF!="Tiếng Việt")) -> #REF! | N5: =SUMPRODUCT(('Phân công'!$D$2:$D$259=$A5)*('Phân công'!#REF!="X")*(RIGHT('Phân công'!$C$2:$C$259,3)="04C")*('Phân công'!#REF!="Tiếng Anh")) -> #REF! | O5: =SUMPRODUCT(('Phân công'!$D$2:$D$259=$A5)*('Phân công'!#REF!="X")*(RIGHT('Phân công'!$C$2:$C$259,3)="14C")*('Phân công'!#REF!="Tiếng Việt")) -> #REF! | P5: =SUMPRODUCT(('Phân công'!$D$2:$D$259=$A5)*('Phân công'!#REF!="X")*(RIGHT('Phân công'!$C$2:$C$259,3)="14C")*('Phân công'!#REF!="Tiếng Anh")) -> #REF! | Q5: =SUMPRODUCT(('Phân công'!$D$2:$D$259=$A5)*('Phân công'!#REF!="X")*(RIGHT('Phân công'!$C$2:$C$259,3)="4CA")) -> #REF! | R5: =SUMPRODUCT(('Phân công'!#REF!='Thù lao'!A5)*(RIGHT('Phân công'!$C$2:$C$259,3)="404")) -> #REF! | S5: =SUMPRODUCT(('Phân công'!#REF!='Thù lao'!A5)*(RIGHT('Phân công'!$C$2:$C$259,3)="412")) -> #REF! | T5: =SUMPRODUCT(('Phân công'!#REF!='Thù lao'!A5)*(RIGHT('Phân công'!$C$2:$C$259,3)="414")) -> #REF! | U5: =SUMPRODUCT(('Phân công'!#REF!='Thù lao'!A5)*(RIGHT('Phân công'!$C$2:$C$259,3)="04C")*('Phân công'!#REF!="Tiếng Việt")) -> #REF! | V5: =SUMPRODUCT(('Phân công'!#REF!='Thù lao'!A5)*(RIGHT('Phân công'!$C$2:$C$259,3)="04C")*('Phân công'!#REF!="Tiếng Anh")) -> #REF! | W5: =SUMPRODUCT(('Phân công'!#REF!='Thù lao'!A5)*(RIGHT('Phân công'!$C$2:$C$259,3)="14C")*('Phân công'!#REF!="Tiếng Việt")) -> #REF! | X5: =SUMPRODUCT(('Phân công'!#REF!='Thù lao'!A5)*(RIGHT('Phân công'!$C$2:$C$259,3)="14C")*('Phân công'!#REF!="Tiếng Anh")) -> #REF! | Y5: =SUMPRODUCT(('Phân công'!#REF!='Thù lao'!A5)*(RIGHT('Phân công'!$C$10:$C$259,3)="4CA")) -> #REF! | Z5: =SUMPRODUCT(('Phân công'!#REF!='Thù lao'!A5)*(RIGHT('Phân công'!$C$2:$C$259,3)="404")) -> #REF! | AA5: =SUMPRODUCT(('Phân công'!#REF!='Thù lao'!A5)*(RIGHT('Phân công'!$C$2:$C$259,3)="412")) -> #REF! | AB5: =SUMPRODUCT(('Phân công'!#REF!='Thù lao'!A5)*(RIGHT('Phân công'!$C$2:$C$259,3)="414")) -> #REF! | AC5: =SUMPRODUCT(('Phân công'!#REF!='Thù lao'!A5)*(RIGHT('Phân công'!$C$2:$C$259,3)="04C")*('Phân công'!#REF!="Tiếng Việt")) -> #REF! | AD5: =SUMPRODUCT(('Phân công'!#REF!='Thù lao'!A5)*(RIGHT('Phân công'!$C$2:$C$259,3)="04C")*('Phân công'!#REF!="Tiếng Anh")) -> #REF! | AE5: =SUMPRODUCT(('Phân công'!#REF!='Thù lao'!A5)*(RIGHT('Phân công'!$C$2:$C$259,3)="14C")*('Phân công'!#REF!="Tiếng Việt")) -> #REF! | AF5: =SUMPRODUCT(('Phân công'!#REF!='Thù lao'!A5)*(RIGHT('Phân công'!$C$2:$C$259,3)="14C")*('Phân công'!#REF!="Tiếng Anh")) -> #REF! | AG5: =SUMPRODUCT(('Phân công'!#REF!='Thù lao'!A5)*(RIGHT('Phân công'!$C$2:$C$259,3)="4CA")) -> #REF! | AH5: =SUMPRODUCT(('Phân công'!#REF!='Thù lao'!A5)*(RIGHT('Phân công'!$C$2:$C$259,3)="404")) -> #REF! | AI5: =SUMPRODUCT(('Phân công'!#REF!='Thù lao'!A5)*(RIGHT('Phân công'!$C$2:$C$259,3)="412")) -> #REF! | AJ5: =SUMPRODUCT(('Phân công'!#REF!='Thù lao'!A5)*(RIGHT('Phân công'!$C$2:$C$259,3)="414")) -> #REF! | AK5: =SUMPRODUCT(('Phân công'!#REF!='Thù lao'!A5)*(RIGHT('Phân công'!$C$2:$C$259,3)="04C")*('Phân công'!#REF!="Tiếng Việt")) -> #REF! | AL5: =SUMPRODUCT(('Phân công'!#REF!='Thù lao'!A5)*(RIGHT('Phân công'!$C$2:$C$259,3)="04C")*('Phân công'!#REF!="Tiếng Anh")) -> #REF! | AM5: =SUMPRODUCT(('Phân công'!#REF!='Thù lao'!A5)*(RIGHT('Phân công'!$C$2:$C$259,3)="14C")*('Phân công'!#REF!="Tiếng Việt")) -> #REF! | AN5: =SUMPRODUCT(('Phân công'!#REF!='Thù lao'!A5)*(RIGHT('Phân công'!$C$2:$C$259,3)="14C")*('Phân công'!#REF!="Tiếng Anh")) -> #REF! | AO5: =SUMPRODUCT(('Phân công'!#REF!='Thù lao'!A5)*(RIGHT('Phân công'!$C$2:$C$259,3)="4CA")) -> #REF! | AP5: =SUMPRODUCT(('Phân công'!#REF!='Thù lao'!A5)*(RIGHT('Phân công'!$C$2:$C$259,3)="404")) -> #REF! | AQ5: =SUMPRODUCT(('Phân công'!#REF!='Thù lao'!A5)*(RIGHT('Phân công'!$C$2:$C$259,3)="412")) -> #REF! | AR5: =SUMPRODUCT(('Phân công'!#REF!='Thù lao'!A5)*(RIGHT('Phân công'!$C$2:$C$259,3)="414")) -> #REF! | AS5: =SUMPRODUCT(('Phân công'!#REF!='Thù lao'!A5)*(RIGHT('Phân công'!$C$2:$C$259,3)="04C")*('Phân công'!#REF!="Tiếng Việt")) -> #REF! | AT5: =SUMPRODUCT(('Phân công'!#REF!='Thù lao'!A5)*(RIGHT('Phân công'!$C$2:$C$259,3)="04C")*('Phân công'!#REF!="Tiếng Anh")) -> #REF! | AU5: =SUMPRODUCT(('Phân công'!#REF!='Thù lao'!A5)*(RIGHT('Phân công'!$C$2:$C$259,3)="14C")*('Phân công'!#REF!="Tiếng Việt")) -> #REF! | AV5: =SUMPRODUCT(('Phân công'!#REF!='Thù lao'!A5)*(RIGHT('Phân công'!$C$2:$C$259,3)="14C")*('Phân công'!#REF!="Tiếng Anh")) -> #REF! | AW5: =SUMPRODUCT(('Phân công'!#REF!='Thù lao'!A5)*(RIGHT('Phân công'!$C$2:$C$259,3)="4CA")) -> #REF! | AX5: =AP5+AH5+Z5+R5 -> #REF! | AY5: =AQ5+AI5+AA5+S5 -> #REF! | AZ5: =AR5+AJ5+AB5+T5 -> #REF! | BA5: =AS5+AK5+AC5+U5 -> #REF! | BB5: =AT5+AL5+AD5+V5 -> #REF! | BC5: =AU5+AM5+AE5+W5 -> #REF! | BD5: =AV5+AN5+AF5+X5 -> #REF! | BE5: =AW5+AO5+AG5+Y5 -> #REF! | BF5: =SUMPRODUCT((B5:I5),($B$3:$I$3))*$BF$2 -> #REF! | BG5: =SUMPRODUCT(R5:Y5,$R$3:$Y$3)*$BG$2 -> #REF! | BH5: =SUMPRODUCT(Z5:AG5,$Z$3:$AG$3)*$BH$2 -> #REF! | BI5: =SUMPRODUCT(AH5:AO5,$AH$3:$AO$3)*$BI$2 -> #REF! | BJ5: =SUMPRODUCT(AP5:AW5,$AP$3:$AW$3)*$BJ$2 -> #REF! | BK5: =SUMPRODUCT((J5:Q5),($J$3:$Q$3))*$BK$2 -> #REF! | BL5: =BF5+BK5 -> #REF! | BM5: =SUM(BG5:BJ5) -> #REF! | BN5: =BM5+BK5 -> #REF! | BO5: =BL5+BM5 -> #REF!
A6: ThS Nguyễn Thị Diễm Hiền | B6: =SUMPRODUCT(('Phân công'!$D$2:$D$259=$A6)*('Phân công'!#REF!="X")*(RIGHT('Phân công'!$C$2:$C$259,3)="404")) -> #REF! | C6: =SUMPRODUCT(('Phân công'!$D$2:$D$259=$A6)*('Phân công'!#REF!="X")*(RIGHT('Phân công'!$C$2:$C$259,3)="412")) -> #REF! | D6: =SUMPRODUCT(('Phân công'!$D$2:$D$259=$A6)*('Phân công'!#REF!="X")*(RIGHT('Phân công'!$C$2:$C$259,3)="414")) -> #REF! | E6: =SUMPRODUCT(('Phân công'!$D$2:$D$259=$A6)*('Phân công'!#REF!="X")*(RIGHT('Phân công'!$C$2:$C$259,4)="404C")*('Phân công'!#REF!="Tiếng Việt")) -> #REF! | F6: =SUMPRODUCT(('Phân công'!$D$2:$D$259=$A6)*('Phân công'!#REF!="X")*(RIGHT('Phân công'!$C$2:$C$259,4)="404C")*('Phân công'!#REF!="Tiếng Anh")) -> #REF! | G6: =SUMPRODUCT(('Phân công'!$D$2:$D$259=$A6)*('Phân công'!#REF!="X")*(RIGHT('Phân công'!$C$2:$C$259,4)="414C")*('Phân công'!#REF!="Tiếng Việt")) -> #REF! | H6: =SUMPRODUCT(('Phân công'!$D$2:$D$259=$A6)*('Phân công'!#REF!="X")*(RIGHT('Phân công'!$C$2:$C$259,4)="414C")*('Phân công'!#REF!="Tiếng Anh")) -> #REF! | I6: =SUMPRODUCT(('Phân công'!$D$2:$D$259=$A6)*('Phân công'!#REF!="X")*(RIGHT('Phân công'!$C$2:$C$259,5)="404CA")) -> #REF! | J6: =SUMPRODUCT(('Phân công'!$D$2:$D$259=$A6)*('Phân công'!#REF!="X")*(RIGHT('Phân công'!$C$2:$C$259,3)="404")) -> #REF! | K6: =SUMPRODUCT(('Phân công'!$D$2:$D$259=$A6)*('Phân công'!#REF!="X")*(RIGHT('Phân công'!$C$2:$C$259,3)="412")) -> #REF! | L6: =SUMPRODUCT(('Phân công'!$D$2:$D$259=$A6)*('Phân công'!#REF!="X")*(RIGHT('Phân công'!$C$2:$C$259,3)="414")) -> #REF! | M6: =SUMPRODUCT(('Phân công'!$D$2:$D$259=$A6)*('Phân công'!#REF!="X")*(RIGHT('Phân công'!$C$2:$C$259,3)="04C")*('Phân công'!#REF!="Tiếng Việt")) -> #REF! | N6: =SUMPRODUCT(('Phân công'!$D$2:$D$259=$A6)*('Phân công'!#REF!="X")*(RIGHT('Phân công'!$C$2:$C$259,3)="04C")*('Phân công'!#REF!="Tiếng Anh")) -> #REF! | O6: =SUMPRODUCT(('Phân công'!$D$2:$D$259=$A6)*('Phân công'!#REF!="X")*(RIGHT('Phân công'!$C$2:$C$259,3)="14C")*('Phân công'!#REF!="Tiếng Việt")) -> #REF! | P6: =SUMPRODUCT(('Phân công'!$D$2:$D$259=$A6)*('Phân công'!#REF!="X")*(RIGHT('Phân công'!$C$2:$C$259,3)="14C")*('Phân công'!#REF!="Tiếng Anh")) -> #REF! | Q6: =SUMPRODUCT(('Phân công'!$D$2:$D$259=$A6)*('Phân công'!#REF!="X")*(RIGHT('Phân công'!$C$2:$C$259,3)="4CA")) -> #REF! | R6: =SUMPRODUCT(('Phân công'!#REF!='Thù lao'!A6)*(RIGHT('Phân công'!$C$2:$C$259,3)="404")) -> #REF! | S6: =SUMPRODUCT(('Phân công'!#REF!='Thù lao'!A6)*(RIGHT('Phân công'!$C$2:$C$259,3)="412")) -> #REF! | T6: =SUMPRODUCT(('Phân công'!#REF!='Thù lao'!A6)*(RIGHT('Phân công'!$C$2:$C$259,3)="414")) -> #REF! | U6: =SUMPRODUCT(('Phân công'!#REF!='Thù lao'!A6)*(RIGHT('Phân công'!$C$2:$C$259,3)="04C")*('Phân công'!#REF!="Tiếng Việt")) -> #REF! | V6: =SUMPRODUCT(('Phân công'!#REF!='Thù lao'!A6)*(RIGHT('Phân công'!$C$2:$C$259,3)="04C")*('Phân công'!#REF!="Tiếng Anh")) -> #REF! | W6: =SUMPRODUCT(('Phân công'!#REF!='Thù lao'!A6)*(RIGHT('Phân công'!$C$2:$C$259,3)="14C")*('Phân công'!#REF!="Tiếng Việt")) -> #REF! | X6: =SUMPRODUCT(('Phân công'!#REF!='Thù lao'!A6)*(RIGHT('Phân công'!$C$2:$C$259,3)="14C")*('Phân công'!#REF!="Tiếng Anh")) -> #REF! | Y6: =SUMPRODUCT(('Phân công'!#REF!='Thù lao'!A6)*(RIGHT('Phân công'!$C$10:$C$259,3)="4CA")) -> #REF! | Z6: =SUMPRODUCT(('Phân công'!#REF!='Thù lao'!A6)*(RIGHT('Phân công'!$C$2:$C$259,3)="404")) -> #REF! | AA6: =SUMPRODUCT(('Phân công'!#REF!='Thù lao'!A6)*(RIGHT('Phân công'!$C$2:$C$259,3)="412")) -> #REF! | AB6: =SUMPRODUCT(('Phân công'!#REF!='Thù lao'!A6)*(RIGHT('Phân công'!$C$2:$C$259,3)="414")) -> #REF! | AC6: =SUMPRODUCT(('Phân công'!#REF!='Thù lao'!A6)*(RIGHT('Phân công'!$C$2:$C$259,3)="04C")*('Phân công'!#REF!="Tiếng Việt")) -> #REF! | AD6: =SUMPRODUCT(('Phân công'!#REF!='Thù lao'!A6)*(RIGHT('Phân công'!$C$2:$C$259,3)="04C")*('Phân công'!#REF!="Tiếng Anh")) -> #REF! | AE6: =SUMPRODUCT(('Phân công'!#REF!='Thù lao'!A6)*(RIGHT('Phân công'!$C$2:$C$259,3)="14C")*('Phân công'!#REF!="Tiếng Việt")) -> #REF! | AF6: =SUMPRODUCT(('Phân công'!#REF!='Thù lao'!A6)*(RIGHT('Phân công'!$C$2:$C$259,3)="14C")*('Phân công'!#REF!="Tiếng Anh")) -> #REF! | AG6: =SUMPRODUCT(('Phân công'!#REF!='Thù lao'!A6)*(RIGHT('Phân công'!$C$2:$C$259,3)="4CA")) -> #REF! | AH6: =SUMPRODUCT(('Phân công'!#REF!='Thù lao'!A6)*(RIGHT('Phân công'!$C$2:$C$259,3)="404")) -> #REF! | AI6: =SUMPRODUCT(('Phân công'!#REF!='Thù lao'!A6)*(RIGHT('Phân công'!$C$2:$C$259,3)="412")) -> #REF! | AJ6: =SUMPRODUCT(('Phân công'!#REF!='Thù lao'!A6)*(RIGHT('Phân công'!$C$2:$C$259,3)="414")) -> #REF! | AK6: =SUMPRODUCT(('Phân công'!#REF!='Thù lao'!A6)*(RIGHT('Phân công'!$C$2:$C$259,3)="04C")*('Phân công'!#REF!="Tiếng Việt")) -> #REF! | AL6: =SUMPRODUCT(('Phân công'!#REF!='Thù lao'!A6)*(RIGHT('Phân công'!$C$2:$C$259,3)="04C")*('Phân công'!#REF!="Tiếng Anh")) -> #REF! | AM6: =SUMPRODUCT(('Phân công'!#REF!='Thù lao'!A6)*(RIGHT('Phân công'!$C$2:$C$259,3)="14C")*('Phân công'!#REF!="Tiếng Việt")) -> #REF! | AN6: =SUMPRODUCT(('Phân công'!#REF!='Thù lao'!A6)*(RIGHT('Phân công'!$C$2:$C$259,3)="14C")*('Phân công'!#REF!="Tiếng Anh")) -> #REF! | AO6: =SUMPRODUCT(('Phân công'!#REF!='Thù lao'!A6)*(RIGHT('Phân công'!$C$2:$C$259,3)="4CA")) -> #REF! | AP6: =SUMPRODUCT(('Phân công'!#REF!='Thù lao'!A6)*(RIGHT('Phân công'!$C$2:$C$259,3)="404")) -> #REF! | AQ6: =SUMPRODUCT(('Phân công'!#REF!='Thù lao'!A6)*(RIGHT('Phân công'!$C$2:$C$259,3)="412")) -> #REF! | AR6: =SUMPRODUCT(('Phân công'!#REF!='Thù lao'!A6)*(RIGHT('Phân công'!$C$2:$C$259,3)="414")) -> #REF! | AS6: =SUMPRODUCT(('Phân công'!#REF!='Thù lao'!A6)*(RIGHT('Phân công'!$C$2:$C$259,3)="04C")*('Phân công'!#REF!="Tiếng Việt")) -> #REF! | AT6: =SUMPRODUCT(('Phân công'!#REF!='Thù lao'!A6)*(RIGHT('Phân công'!$C$2:$C$259,3)="04C")*('Phân công'!#REF!="Tiếng Anh")) -> #REF! | AU6: =SUMPRODUCT(('Phân công'!#REF!='Thù lao'!A6)*(RIGHT('Phân công'!$C$2:$C$259,3)="14C")*('Phân công'!#REF!="Tiếng Việt")) -> #REF! | AV6: =SUMPRODUCT(('Phân công'!#REF!='Thù lao'!A6)*(RIGHT('Phân công'!$C$2:$C$259,3)="14C")*('Phân công'!#REF!="Tiếng Anh")) -> #REF! | AW6: =SUMPRODUCT(('Phân công'!#REF!='Thù lao'!A6)*(RIGHT('Phân công'!$C$2:$C$259,3)="4CA")) -> #REF! | AX6: =AP6+AH6+Z6+R6 -> #REF! | AY6: =AQ6+AI6+AA6+S6 -> #REF! | AZ6: =AR6+AJ6+AB6+T6 -> #REF! | BA6: =AS6+AK6+AC6+U6 -> #REF! | BB6: =AT6+AL6+AD6+V6 -> #REF! | BC6: =AU6+AM6+AE6+W6 -> #REF! | BD6: =AV6+AN6+AF6+X6 -> #REF! | BE6: =AW6+AO6+AG6+Y6 -> #REF! | BF6: =SUMPRODUCT((B6:I6),($B$3:$I$3))*$BF$2 -> #REF! | BG6: =SUMPRODUCT(R6:Y6,$R$3:$Y$3)*$BG$2 -> #REF! | BH6: =SUMPRODUCT(Z6:AG6,$Z$3:$AG$3)*$BH$2 -> #REF! | BI6: =SUMPRODUCT(AH6:AO6,$AH$3:$AO$3)*$BI$2 -> #REF! | BJ6: =SUMPRODUCT(AP6:AW6,$AP$3:$AW$3)*$BJ$2 -> #REF! | BK6: =SUMPRODUCT((J6:Q6),($J$3:$Q$3))*$BK$2 -> #REF! | BL6: =BF6+BK6 -> #REF! | BM6: =SUM(BG6:BJ6) -> #REF! | BN6: =BM6+BK6 -> #REF! | BO6: =BL6+BM6 -> #REF!
A7: TS Nguyễn Trung Hiếu | B7: =SUMPRODUCT(('Phân công'!$D$2:$D$259=$A7)*('Phân công'!#REF!="X")*(RIGHT('Phân công'!$C$2:$C$259,3)="404")) -> #REF! | C7: =SUMPRODUCT(('Phân công'!$D$2:$D$259=$A7)*('Phân công'!#REF!="X")*(RIGHT('Phân công'!$C$2:$C$259,3)="412")) -> #REF! | D7: =SUMPRODUCT(('Phân công'!$D$2:$D$259=$A7)*('Phân công'!#REF!="X")*(RIGHT('Phân công'!$C$2:$C$259,3)="414")) -> #REF! | E7: =SUMPRODUCT(('Phân công'!$D$2:$D$259=$A7)*('Phân công'!#REF!="X")*(RIGHT('Phân công'!$C$2:$C$259,4)="404C")*('Phân công'!#REF!="Tiếng Việt")) -> #REF! | F7: =SUMPRODUCT(('Phân công'!$D$2:$D$259=$A7)*('Phân công'!#REF!="X")*(RIGHT('Phân công'!$C$2:$C$259,4)="404C")*('Phân công'!#REF!="Tiếng Anh")) -> #REF! | G7: =SUMPRODUCT(('Phân công'!$D$2:$D$259=$A7)*('Phân công'!#REF!="X")*(RIGHT('Phân công'!$C$2:$C$259,4)="414C")*('Phân công'!#REF!="Tiếng Việt")) -> #REF! | H7: =SUMPRODUCT(('Phân công'!$D$2:$D$259=$A7)*('Phân công'!#REF!="X")*(RIGHT('Phân công'!$C$2:$C$259,4)="414C")*('Phân công'!#REF!="Tiếng Anh")) -> #REF! | I7: =SUMPRODUCT(('Phân công'!$D$2:$D$259=$A7)*('Phân công'!#REF!="X")*(RIGHT('Phân công'!$C$2:$C$259,5)="404CA")) -> #REF! | J7: =SUMPRODUCT(('Phân công'!$D$2:$D$259=$A7)*('Phân công'!#REF!="X")*(RIGHT('Phân công'!$C$2:$C$259,3)="404")) -> #REF! | K7: =SUMPRODUCT(('Phân công'!$D$2:$D$259=$A7)*('Phân công'!#REF!="X")*(RIGHT('Phân công'!$C$2:$C$259,3)="412")) -> #REF! | L7: =SUMPRODUCT(('Phân công'!$D$2:$D$259=$A7)*('Phân công'!#REF!="X")*(RIGHT('Phân công'!$C$2:$C$259,3)="414")) -> #REF! | M7: =SUMPRODUCT(('Phân công'!$D$2:$D$259=$A7)*('Phân công'!#REF!="X")*(RIGHT('Phân công'!$C$2:$C$259,3)="04C")*('Phân công'!#REF!="Tiếng Việt")) -> #REF! | N7: =SUMPRODUCT(('Phân công'!$D$2:$D$259=$A7)*('Phân công'!#REF!="X")*(RIGHT('Phân công'!$C$2:$C$259,3)="04C")*('Phân công'!#REF!="Tiếng Anh")) -> #REF! | O7: =SUMPRODUCT(('Phân công'!$D$2:$D$259=$A7)*('Phân công'!#REF!="X")*(RIGHT('Phân công'!$C$2:$C$259,3)="14C")*('Phân công'!#REF!="Tiếng Việt")) -> #REF! | P7: =SUMPRODUCT(('Phân công'!$D$2:$D$259=$A7)*('Phân công'!#REF!="X")*(RIGHT('Phân công'!$C$2:$C$259,3)="14C")*('Phân công'!#REF!="Tiếng Anh")) -> #REF! | Q7: =SUMPRODUCT(('Phân công'!$D$2:$D$259=$A7)*('Phân công'!#REF!="X")*(RIGHT('Phân công'!$C$2:$C$259,3)="4CA")) -> #REF! | R7: =SUMPRODUCT(('Phân công'!#REF!='Thù lao'!A7)*(RIGHT('Phân công'!$C$2:$C$259,3)="404")) -> #REF! | S7: =SUMPRODUCT(('Phân công'!#REF!='Thù lao'!A7)*(RIGHT('Phân công'!$C$2:$C$259,3)="412")) -> #REF! | T7: =SUMPRODUCT(('Phân công'!#REF!='Thù lao'!A7)*(RIGHT('Phân công'!$C$2:$C$259,3)="414")) -> #REF! | U7: =SUMPRODUCT(('Phân công'!#REF!='Thù lao'!A7)*(RIGHT('Phân công'!$C$2:$C$259,3)="04C")*('Phân công'!#REF!="Tiếng Việt")) -> #REF! | V7: =SUMPRODUCT(('Phân công'!#REF!='Thù lao'!A7)*(RIGHT('Phân công'!$C$2:$C$259,3)="04C")*('Phân công'!#REF!="Tiếng Anh")) -> #REF! | W7: =SUMPRODUCT(('Phân công'!#REF!='Thù lao'!A7)*(RIGHT('Phân công'!$C$2:$C$259,3)="14C")*('Phân công'!#REF!="Tiếng Việt")) -> #REF! | X7: =SUMPRODUCT(('Phân công'!#REF!='Thù lao'!A7)*(RIGHT('Phân công'!$C$2:$C$259,3)="14C")*('Phân công'!#REF!="Tiếng Anh")) -> #REF! | Y7: =SUMPRODUCT(('Phân công'!#REF!='Thù lao'!A7)*(RIGHT('Phân công'!$C$10:$C$259,3)="4CA")) -> #REF! | Z7: =SUMPRODUCT(('Phân công'!#REF!='Thù lao'!A7)*(RIGHT('Phân công'!$C$2:$C$259,3)="404")) -> #REF! | AA7: =SUMPRODUCT(('Phân công'!#REF!='Thù lao'!A7)*(RIGHT('Phân công'!$C$2:$C$259,3)="412")) -> #REF! | AB7: =SUMPRODUCT(('Phân công'!#REF!='Thù lao'!A7)*(RIGHT('Phân công'!$C$2:$C$259,3)="414")) -> #REF! | AC7: =SUMPRODUCT(('Phân công'!#REF!='Thù lao'!A7)*(RIGHT('Phân công'!$C$2:$C$259,3)="04C")*('Phân công'!#REF!="Tiếng Việt")) -> #REF! | AD7: =SUMPRODUCT(('Phân công'!#REF!='Thù lao'!A7)*(RIGHT('Phân công'!$C$2:$C$259,3)="04C")*('Phân công'!#REF!="Tiếng Anh")) -> #REF! | AE7: =SUMPRODUCT(('Phân công'!#REF!='Thù lao'!A7)*(RIGHT('Phân công'!$C$2:$C$259,3)="14C")*('Phân công'!#REF!="Tiếng Việt")) -> #REF! | AF7: =SUMPRODUCT(('Phân công'!#REF!='Thù lao'!A7)*(RIGHT('Phân công'!$C$2:$C$259,3)="14C")*('Phân công'!#REF!="Tiếng Anh")) -> #REF! | AG7: =SUMPRODUCT(('Phân công'!#REF!='Thù lao'!A7)*(RIGHT('Phân công'!$C$2:$C$259,3)="4CA")) -> #REF! | AH7: =SUMPRODUCT(('Phân công'!#REF!='Thù lao'!A7)*(RIGHT('Phân công'!$C$2:$C$259,3)="404")) -> #REF! | AI7: =SUMPRODUCT(('Phân công'!#REF!='Thù lao'!A7)*(RIGHT('Phân công'!$C$2:$C$259,3)="412")) -> #REF! | AJ7: =SUMPRODUCT(('Phân công'!#REF!='Thù lao'!A7)*(RIGHT('Phân công'!$C$2:$C$259,3)="414")) -> #REF! | AK7: =SUMPRODUCT(('Phân công'!#REF!='Thù lao'!A7)*(RIGHT('Phân công'!$C$2:$C$259,3)="04C")*('Phân công'!#REF!="Tiếng Việt")) -> #REF! | AL7: =SUMPRODUCT(('Phân công'!#REF!='Thù lao'!A7)*(RIGHT('Phân công'!$C$2:$C$259,3)="04C")*('Phân công'!#REF!="Tiếng Anh")) -> #REF! | AM7: =SUMPRODUCT(('Phân công'!#REF!='Thù lao'!A7)*(RIGHT('Phân công'!$C$2:$C$259,3)="14C")*('Phân công'!#REF!="Tiếng Việt")) -> #REF! | AN7: =SUMPRODUCT(('Phân công'!#REF!='Thù lao'!A7)*(RIGHT('Phân công'!$C$2:$C$259,3)="14C")*('Phân công'!#REF!="Tiếng Anh")) -> #REF! | AO7: =SUMPRODUCT(('Phân công'!#REF!='Thù lao'!A7)*(RIGHT('Phân công'!$C$2:$C$259,3)="4CA")) -> #REF! | AP7: =SUMPRODUCT(('Phân công'!#REF!='Thù lao'!A7)*(RIGHT('Phân công'!$C$2:$C$259,3)="404")) -> #REF! | AQ7: =SUMPRODUCT(('Phân công'!#REF!='Thù lao'!A7)*(RIGHT('Phân công'!$C$2:$C$259,3)="412")) -> #REF! | AR7: =SUMPRODUCT(('Phân công'!#REF!='Thù lao'!A7)*(RIGHT('Phân công'!$C$2:$C$259,3)="414")) -> #REF! | AS7: =SUMPRODUCT(('Phân công'!#REF!='Thù lao'!A7)*(RIGHT('Phân công'!$C$2:$C$259,3)="04C")*('Phân công'!#REF!="Tiếng Việt")) -> #REF! | AT7: =SUMPRODUCT(('Phân công'!#REF!='Thù lao'!A7)*(RIGHT('Phân công'!$C$2:$C$259,3)="04C")*('Phân công'!#REF!="Tiếng Anh")) -> #REF! | AU7: =SUMPRODUCT(('Phân công'!#REF!='Thù lao'!A7)*(RIGHT('Phân công'!$C$2:$C$259,3)="14C")*('Phân công'!#REF!="Tiếng Việt")) -> #REF! | AV7: =SUMPRODUCT(('Phân công'!#REF!='Thù lao'!A7)*(RIGHT('Phân công'!$C$2:$C$259,3)="14C")*('Phân công'!#REF!="Tiếng Anh")) -> #REF! | AW7: =SUMPRODUCT(('Phân công'!#REF!='Thù lao'!A7)*(RIGHT('Phân công'!$C$2:$C$259,3)="4CA")) -> #REF! | AX7: =AP7+AH7+Z7+R7 -> #REF! | AY7: =AQ7+AI7+AA7+S7 -> #REF! | AZ7: =AR7+AJ7+AB7+T7 -> #REF! | BA7: =AS7+AK7+AC7+U7 -> #REF! | BB7: =AT7+AL7+AD7+V7 -> #REF! | BC7: =AU7+AM7+AE7+W7 -> #REF! | BD7: =AV7+AN7+AF7+X7 -> #REF! | BE7: =AW7+AO7+AG7+Y7 -> #REF! | BF7: =SUMPRODUCT((B7:I7),($B$3:$I$3))*$BF$2 -> #REF! | BG7: =SUMPRODUCT(R7:Y7,$R$3:$Y$3)*$BG$2 -> #REF! | BH7: =SUMPRODUCT(Z7:AG7,$Z$3:$AG$3)*$BH$2 -> #REF! | BI7: =SUMPRODUCT(AH7:AO7,$AH$3:$AO$3)*$BI$2 -> #REF! | BJ7: =SUMPRODUCT(AP7:AW7,$AP$3:$AW$3)*$BJ$2 -> #REF! | BK7: =SUMPRODUCT((J7:Q7),($J$3:$Q$3))*$BK$2 -> #REF! | BL7: =BF7+BK7 -> #REF! | BM7: =SUM(BG7:BJ7) -> #REF! | BN7: =BM7+BK7 -> #REF! | BO7: =BL7+BM7 -> #REF!
A8: ThS Phạm Chí Khoa | B8: =SUMPRODUCT(('Phân công'!$D$2:$D$259=$A8)*('Phân công'!#REF!="X")*(RIGHT('Phân công'!$C$2:$C$259,3)="404")) -> #REF! | C8: =SUMPRODUCT(('Phân công'!$D$2:$D$259=$A8)*('Phân công'!#REF!="X")*(RIGHT('Phân công'!$C$2:$C$259,3)="412")) -> #REF! | D8: =SUMPRODUCT(('Phân công'!$D$2:$D$259=$A8)*('Phân công'!#REF!="X")*(RIGHT('Phân công'!$C$2:$C$259,3)="414")) -> #REF! | E8: =SUMPRODUCT(('Phân công'!$D$2:$D$259=$A8)*('Phân công'!#REF!="X")*(RIGHT('Phân công'!$C$2:$C$259,4)="404C")*('Phân công'!#REF!="Tiếng Việt")) -> #REF! | F8: =SUMPRODUCT(('Phân công'!$D$2:$D$259=$A8)*('Phân công'!#REF!="X")*(RIGHT('Phân công'!$C$2:$C$259,4)="404C")*('Phân công'!#REF!="Tiếng Anh")) -> #REF! | G8: =SUMPRODUCT(('Phân công'!$D$2:$D$259=$A8)*('Phân công'!#REF!="X")*(RIGHT('Phân công'!$C$2:$C$259,4)="414C")*('Phân công'!#REF!="Tiếng Việt")) -> #REF! | H8: =SUMPRODUCT(('Phân công'!$D$2:$D$259=$A8)*('Phân công'!#REF!="X")*(RIGHT('Phân công'!$C$2:$C$259,4)="414C")*('Phân công'!#REF!="Tiếng Anh")) -> #REF! | I8: =SUMPRODUCT(('Phân công'!$D$2:$D$259=$A8)*('Phân công'!#REF!="X")*(RIGHT('Phân công'!$C$2:$C$259,5)="404CA")) -> #REF! | J8: =SUMPRODUCT(('Phân công'!$D$2:$D$259=$A8)*('Phân công'!#REF!="X")*(RIGHT('Phân công'!$C$2:$C$259,3)="404")) -> #REF! | K8: =SUMPRODUCT(('Phân công'!$D$2:$D$259=$A8)*('Phân công'!#REF!="X")*(RIGHT('Phân công'!$C$2:$C$259,3)="412")) -> #REF! | L8: =SUMPRODUCT(('Phân công'!$D$2:$D$259=$A8)*('Phân công'!#REF!="X")*(RIGHT('Phân công'!$C$2:$C$259,3)="414")) -> #REF! | M8: =SUMPRODUCT(('Phân công'!$D$2:$D$259=$A8)*('Phân công'!#REF!="X")*(RIGHT('Phân công'!$C$2:$C$259,3)="04C")*('Phân công'!#REF!="Tiếng Việt")) -> #REF! | N8: =SUMPRODUCT(('Phân công'!$D$2:$D$259=$A8)*('Phân công'!#REF!="X")*(RIGHT('Phân công'!$C$2:$C$259,3)="04C")*('Phân công'!#REF!="Tiếng Anh")) -> #REF! | O8: =SUMPRODUCT(('Phân công'!$D$2:$D$259=$A8)*('Phân công'!#REF!="X")*(RIGHT('Phân công'!$C$2:$C$259,3)="14C")*('Phân công'!#REF!="Tiếng Việt")) -> #REF! | P8: =SUMPRODUCT(('Phân công'!$D$2:$D$259=$A8)*('Phân công'!#REF!="X")*(RIGHT('Phân công'!$C$2:$C$259,3)="14C")*('Phân công'!#REF!="Tiếng Anh")) -> #REF! | Q8: =SUMPRODUCT(('Phân công'!$D$2:$D$259=$A8)*('Phân công'!#REF!="X")*(RIGHT('Phân công'!$C$2:$C$259,3)="4CA")) -> #REF! | R8: =SUMPRODUCT(('Phân công'!#REF!='Thù lao'!A8)*(RIGHT('Phân công'!$C$2:$C$259,3)="404")) -> #REF! | S8: =SUMPRODUCT(('Phân công'!#REF!='Thù lao'!A8)*(RIGHT('Phân công'!$C$2:$C$259,3)="412")) -> #REF! | T8: =SUMPRODUCT(('Phân công'!#REF!='Thù lao'!A8)*(RIGHT('Phân công'!$C$2:$C$259,3)="414")) -> #REF! | U8: =SUMPRODUCT(('Phân công'!#REF!='Thù lao'!A8)*(RIGHT('Phân công'!$C$2:$C$259,3)="04C")*('Phân công'!#REF!="Tiếng Việt")) -> #REF! | V8: =SUMPRODUCT(('Phân công'!#REF!='Thù lao'!A8)*(RIGHT('Phân công'!$C$2:$C$259,3)="04C")*('Phân công'!#REF!="Tiếng Anh")) -> #REF! | W8: =SUMPRODUCT(('Phân công'!#REF!='Thù lao'!A8)*(RIGHT('Phân công'!$C$2:$C$259,3)="14C")*('Phân công'!#REF!="Tiếng Việt")) -> #REF! | X8: =SUMPRODUCT(('Phân công'!#REF!='Thù lao'!A8)*(RIGHT('Phân công'!$C$2:$C$259,3)="14C")*('Phân công'!#REF!="Tiếng Anh")) -> #REF! | Y8: =SUMPRODUCT(('Phân công'!#REF!='Thù lao'!A8)*(RIGHT('Phân công'!$C$10:$C$259,3)="4CA")) -> #REF! | Z8: =SUMPRODUCT(('Phân công'!#REF!='Thù lao'!A8)*(RIGHT('Phân công'!$C$2:$C$259,3)="404")) -> #REF! | AA8: =SUMPRODUCT(('Phân công'!#REF!='Thù lao'!A8)*(RIGHT('Phân công'!$C$2:$C$259,3)="412")) -> #REF! | AB8: =SUMPRODUCT(('Phân công'!#REF!='Thù lao'!A8)*(RIGHT('Phân công'!$C$2:$C$259,3)="414")) -> #REF! | AC8: =SUMPRODUCT(('Phân công'!#REF!='Thù lao'!A8)*(RIGHT('Phân công'!$C$2:$C$259,3)="04C")*('Phân công'!#REF!="Tiếng Việt")) -> #REF! | AD8: =SUMPRODUCT(('Phân công'!#REF!='Thù lao'!A8)*(RIGHT('Phân công'!$C$2:$C$259,3)="04C")*('Phân công'!#REF!="Tiếng Anh")) -> #REF! | AE8: =SUMPRODUCT(('Phân công'!#REF!='Thù lao'!A8)*(RIGHT('Phân công'!$C$2:$C$259,3)="14C")*('Phân công'!#REF!="Tiếng Việt")) -> #REF! | AF8: =SUMPRODUCT(('Phân công'!#REF!='Thù lao'!A8)*(RIGHT('Phân công'!$C$2:$C$259,3)="14C")*('Phân công'!#REF!="Tiếng Anh")) -> #REF! | AG8: =SUMPRODUCT(('Phân công'!#REF!='Thù lao'!A8)*(RIGHT('Phân công'!$C$2:$C$259,3)="4CA")) -> #REF! | AH8: =SUMPRODUCT(('Phân công'!#REF!='Thù lao'!A8)*(RIGHT('Phân công'!$C$2:$C$259,3)="404")) -> #REF! | AI8: =SUMPRODUCT(('Phân công'!#REF!='Thù lao'!A8)*(RIGHT('Phân công'!$C$2:$C$259,3)="412")) -> #REF! | AJ8: =SUMPRODUCT(('Phân công'!#REF!='Thù lao'!A8)*(RIGHT('Phân công'!$C$2:$C$259,3)="414")) -> #REF! | AK8: =SUMPRODUCT(('Phân công'!#REF!='Thù lao'!A8)*(RIGHT('Phân công'!$C$2:$C$259,3)="04C")*('Phân công'!#REF!="Tiếng Việt")) -> #REF! | AL8: =SUMPRODUCT(('Phân công'!#REF!='Thù lao'!A8)*(RIGHT('Phân công'!$C$2:$C$259,3)="04C")*('Phân công'!#REF!="Tiếng Anh")) -> #REF! | AM8: =SUMPRODUCT(('Phân công'!#REF!='Thù lao'!A8)*(RIGHT('Phân công'!$C$2:$C$259,3)="14C")*('Phân công'!#REF!="Tiếng Việt")) -> #REF! | AN8: =SUMPRODUCT(('Phân công'!#REF!='Thù lao'!A8)*(RIGHT('Phân công'!$C$2:$C$259,3)="14C")*('Phân công'!#REF!="Tiếng Anh")) -> #REF! | AO8: =SUMPRODUCT(('Phân công'!#REF!='Thù lao'!A8)*(RIGHT('Phân công'!$C$2:$C$259,3)="4CA")) -> #REF! | AP8: =SUMPRODUCT(('Phân công'!#REF!='Thù lao'!A8)*(RIGHT('Phân công'!$C$2:$C$259,3)="404")) -> #REF! | AQ8: =SUMPRODUCT(('Phân công'!#REF!='Thù lao'!A8)*(RIGHT('Phân công'!$C$2:$C$259,3)="412")) -> #REF! | AR8: =SUMPRODUCT(('Phân công'!#REF!='Thù lao'!A8)*(RIGHT('Phân công'!$C$2:$C$259,3)="414")) -> #REF! | AS8: =SUMPRODUCT(('Phân công'!#REF!='Thù lao'!A8)*(RIGHT('Phân công'!$C$2:$C$259,3)="04C")*('Phân công'!#REF!="Tiếng Việt")) -> #REF! | AT8: =SUMPRODUCT(('Phân công'!#REF!='Thù lao'!A8)*(RIGHT('Phân công'!$C$2:$C$259,3)="04C")*('Phân công'!#REF!="Tiếng Anh")) -> #REF! | AU8: =SUMPRODUCT(('Phân công'!#REF!='Thù lao'!A8)*(RIGHT('Phân công'!$C$2:$C$259,3)="14C")*('Phân công'!#REF!="Tiếng Việt")) -> #REF! | AV8: =SUMPRODUCT(('Phân công'!#REF!='Thù lao'!A8)*(RIGHT('Phân công'!$C$2:$C$259,3)="14C")*('Phân công'!#REF!="Tiếng Anh")) -> #REF! | AW8: =SUMPRODUCT(('Phân công'!#REF!='Thù lao'!A8)*(RIGHT('Phân công'!$C$2:$C$259,3)="4CA")) -> #REF! | AX8: =AP8+AH8+Z8+R8 -> #REF! | AY8: =AQ8+AI8+AA8+S8 -> #REF! | AZ8: =AR8+AJ8+AB8+T8 -> #REF! | BA8: =AS8+AK8+AC8+U8 -> #REF! | BB8: =AT8+AL8+AD8+V8 -> #REF! | BC8: =AU8+AM8+AE8+W8 -> #REF! | BD8: =AV8+AN8+AF8+X8 -> #REF! | BE8: =AW8+AO8+AG8+Y8 -> #REF! | BF8: =SUMPRODUCT((B8:I8),($B$3:$I$3))*$BF$2 -> #REF! | BG8: =SUMPRODUCT(R8:Y8,$R$3:$Y$3)*$BG$2 -> #REF! | BH8: =SUMPRODUCT(Z8:AG8,$Z$3:$AG$3)*$BH$2 -> #REF! | BI8: =SUMPRODUCT(AH8:AO8,$AH$3:$AO$3)*$BI$2 -> #REF! | BJ8: =SUMPRODUCT(AP8:AW8,$AP$3:$AW$3)*$BJ$2 -> #REF! | BK8: =SUMPRODUCT((J8:Q8),($J$3:$Q$3))*$BK$2 -> #REF! | BL8: =BF8+BK8 -> #REF! | BM8: =SUM(BG8:BJ8) -> #REF! | BN8: =BM8+BK8 -> #REF! | BO8: =BL8+BM8 -> #REF!
A9: TS Nguyễn Thanh Liêm | B9: =SUMPRODUCT(('Phân công'!$D$2:$D$259=$A9)*('Phân công'!#REF!="X")*(RIGHT('Phân công'!$C$2:$C$259,3)="404")) -> #REF! | C9: =SUMPRODUCT(('Phân công'!$D$2:$D$259=$A9)*('Phân công'!#REF!="X")*(RIGHT('Phân công'!$C$2:$C$259,3)="412")) -> #REF! | D9: =SUMPRODUCT(('Phân công'!$D$2:$D$259=$A9)*('Phân công'!#REF!="X")*(RIGHT('Phân công'!$C$2:$C$259,3)="414")) -> #REF! | E9: =SUMPRODUCT(('Phân công'!$D$2:$D$259=$A9)*('Phân công'!#REF!="X")*(RIGHT('Phân công'!$C$2:$C$259,4)="404C")*('Phân công'!#REF!="Tiếng Việt")) -> #REF! | F9: =SUMPRODUCT(('Phân công'!$D$2:$D$259=$A9)*('Phân công'!#REF!="X")*(RIGHT('Phân công'!$C$2:$C$259,4)="404C")*('Phân công'!#REF!="Tiếng Anh")) -> #REF! | G9: =SUMPRODUCT(('Phân công'!$D$2:$D$259=$A9)*('Phân công'!#REF!="X")*(RIGHT('Phân công'!$C$2:$C$259,4)="414C")*('Phân công'!#REF!="Tiếng Việt")) -> #REF! | H9: =SUMPRODUCT(('Phân công'!$D$2:$D$259=$A9)*('Phân công'!#REF!="X")*(RIGHT('Phân công'!$C$2:$C$259,4)="414C")*('Phân công'!#REF!="Tiếng Anh")) -> #REF! | I9: =SUMPRODUCT(('Phân công'!$D$2:$D$259=$A9)*('Phân công'!#REF!="X")*(RIGHT('Phân công'!$C$2:$C$259,5)="404CA")) -> #REF! | J9: =SUMPRODUCT(('Phân công'!$D$2:$D$259=$A9)*('Phân công'!#REF!="X")*(RIGHT('Phân công'!$C$2:$C$259,3)="404")) -> #REF! | K9: =SUMPRODUCT(('Phân công'!$D$2:$D$259=$A9)*('Phân công'!#REF!="X")*(RIGHT('Phân công'!$C$2:$C$259,3)="412")) -> #REF! | L9: =SUMPRODUCT(('Phân công'!$D$2:$D$259=$A9)*('Phân công'!#REF!="X")*(RIGHT('Phân công'!$C$2:$C$259,3)="414")) -> #REF! | M9: =SUMPRODUCT(('Phân công'!$D$2:$D$259=$A9)*('Phân công'!#REF!="X")*(RIGHT('Phân công'!$C$2:$C$259,3)="04C")*('Phân công'!#REF!="Tiếng Việt")) -> #REF! | N9: =SUMPRODUCT(('Phân công'!$D$2:$D$259=$A9)*('Phân công'!#REF!="X")*(RIGHT('Phân công'!$C$2:$C$259,3)="04C")*('Phân công'!#REF!="Tiếng Anh")) -> #REF! | O9: =SUMPRODUCT(('Phân công'!$D$2:$D$259=$A9)*('Phân công'!#REF!="X")*(RIGHT('Phân công'!$C$2:$C$259,3)="14C")*('Phân công'!#REF!="Tiếng Việt")) -> #REF! | P9: =SUMPRODUCT(('Phân công'!$D$2:$D$259=$A9)*('Phân công'!#REF!="X")*(RIGHT('Phân công'!$C$2:$C$259,3)="14C")*('Phân công'!#REF!="Tiếng Anh")) -> #REF! | Q9: =SUMPRODUCT(('Phân công'!$D$2:$D$259=$A9)*('Phân công'!#REF!="X")*(RIGHT('Phân công'!$C$2:$C$259,3)="4CA")) -> #REF! | R9: =SUMPRODUCT(('Phân công'!#REF!='Thù lao'!A9)*(RIGHT('Phân công'!$C$2:$C$259,3)="404")) -> #REF! | S9: =SUMPRODUCT(('Phân công'!#REF!='Thù lao'!A9)*(RIGHT('Phân công'!$C$2:$C$259,3)="412")) -> #REF! | T9: =SUMPRODUCT(('Phân công'!#REF!='Thù lao'!A9)*(RIGHT('Phân công'!$C$2:$C$259,3)="414")) -> #REF! | U9: =SUMPRODUCT(('Phân công'!#REF!='Thù lao'!A9)*(RIGHT('Phân công'!$C$2:$C$259,3)="04C")*('Phân công'!#REF!="Tiếng Việt")) -> #REF! | V9: =SUMPRODUCT(('Phân công'!#REF!='Thù lao'!A9)*(RIGHT('Phân công'!$C$2:$C$259,3)="04C")*('Phân công'!#REF!="Tiếng Anh")) -> #REF! | W9: =SUMPRODUCT(('Phân công'!#REF!='Thù lao'!A9)*(RIGHT('Phân công'!$C$2:$C$259,3)="14C")*('Phân công'!#REF!="Tiếng Việt")) -> #REF! | X9: =SUMPRODUCT(('Phân công'!#REF!='Thù lao'!A9)*(RIGHT('Phân công'!$C$2:$C$259,3)="14C")*('Phân công'!#REF!="Tiếng Anh")) -> #REF! | Y9: =SUMPRODUCT(('Phân công'!#REF!='Thù lao'!A9)*(RIGHT('Phân công'!$C$10:$C$259,3)="4CA")) -> #REF! | Z9: =SUMPRODUCT(('Phân công'!#REF!='Thù lao'!A9)*(RIGHT('Phân công'!$C$2:$C$259,3)="404")) -> #REF! | AA9: =SUMPRODUCT(('Phân công'!#REF!='Thù lao'!A9)*(RIGHT('Phân công'!$C$2:$C$259,3)="412")) -> #REF! | AB9: =SUMPRODUCT(('Phân công'!#REF!='Thù lao'!A9)*(RIGHT('Phân công'!$C$2:$C$259,3)="414")) -> #REF! | AC9: =SUMPRODUCT(('Phân công'!#REF!='Thù lao'!A9)*(RIGHT('Phân công'!$C$2:$C$259,3)="04C")*('Phân công'!#REF!="Tiếng Việt")) -> #REF! | AD9: =SUMPRODUCT(('Phân công'!#REF!='Thù lao'!A9)*(RIGHT('Phân công'!$C$2:$C$259,3)="04C")*('Phân công'!#REF!="Tiếng Anh")) -> #REF! | AE9: =SUMPRODUCT(('Phân công'!#REF!='Thù lao'!A9)*(RIGHT('Phân công'!$C$2:$C$259,3)="14C")*('Phân công'!#REF!="Tiếng Việt")) -> #REF! | AF9: =SUMPRODUCT(('Phân công'!#REF!='Thù lao'!A9)*(RIGHT('Phân công'!$C$2:$C$259,3)="14C")*('Phân công'!#REF!="Tiếng Anh")) -> #REF! | AG9: =SUMPRODUCT(('Phân công'!#REF!='Thù lao'!A9)*(RIGHT('Phân công'!$C$2:$C$259,3)="4CA")) -> #REF! | AH9: =SUMPRODUCT(('Phân công'!#REF!='Thù lao'!A9)*(RIGHT('Phân công'!$C$2:$C$259,3)="404")) -> #REF! | AI9: =SUMPRODUCT(('Phân công'!#REF!='Thù lao'!A9)*(RIGHT('Phân công'!$C$2:$C$259,3)="412")) -> #REF! | AJ9: =SUMPRODUCT(('Phân công'!#REF!='Thù lao'!A9)*(RIGHT('Phân công'!$C$2:$C$259,3)="414")) -> #REF! | AK9: =SUMPRODUCT(('Phân công'!#REF!='Thù lao'!A9)*(RIGHT('Phân công'!$C$2:$C$259,3)="04C")*('Phân công'!#REF!="Tiếng Việt")) -> #REF! | AL9: =SUMPRODUCT(('Phân công'!#REF!='Thù lao'!A9)*(RIGHT('Phân công'!$C$2:$C$259,3)="04C")*('Phân công'!#REF!="Tiếng Anh")) -> #REF! | AM9: =SUMPRODUCT(('Phân công'!#REF!='Thù lao'!A9)*(RIGHT('Phân công'!$C$2:$C$259,3)="14C")*('Phân công'!#REF!="Tiếng Việt")) -> #REF! | AN9: =SUMPRODUCT(('Phân công'!#REF!='Thù lao'!A9)*(RIGHT('Phân công'!$C$2:$C$259,3)="14C")*('Phân công'!#REF!="Tiếng Anh")) -> #REF! | AO9: =SUMPRODUCT(('Phân công'!#REF!='Thù lao'!A9)*(RIGHT('Phân công'!$C$2:$C$259,3)="4CA")) -> #REF! | AP9: =SUMPRODUCT(('Phân công'!#REF!='Thù lao'!A9)*(RIGHT('Phân công'!$C$2:$C$259,3)="404")) -> #REF! | AQ9: =SUMPRODUCT(('Phân công'!#REF!='Thù lao'!A9)*(RIGHT('Phân công'!$C$2:$C$259,3)="412")) -> #REF! | AR9: =SUMPRODUCT(('Phân công'!#REF!='Thù lao'!A9)*(RIGHT('Phân công'!$C$2:$C$259,3)="414")) -> #REF! | AS9: =SUMPRODUCT(('Phân công'!#REF!='Thù lao'!A9)*(RIGHT('Phân công'!$C$2:$C$259,3)="04C")*('Phân công'!#REF!="Tiếng Việt")) -> #REF! | AT9: =SUMPRODUCT(('Phân công'!#REF!='Thù lao'!A9)*(RIGHT('Phân công'!$C$2:$C$259,3)="04C")*('Phân công'!#REF!="Tiếng Anh")) -> #REF! | AU9: =SUMPRODUCT(('Phân công'!#REF!='Thù lao'!A9)*(RIGHT('Phân công'!$C$2:$C$259,3)="14C")*('Phân công'!#REF!="Tiếng Việt")) -> #REF! | AV9: =SUMPRODUCT(('Phân công'!#REF!='Thù lao'!A9)*(RIGHT('Phân công'!$C$2:$C$259,3)="14C")*('Phân công'!#REF!="Tiếng Anh")) -> #REF! | AW9: =SUMPRODUCT(('Phân công'!#REF!='Thù lao'!A9)*(RIGHT('Phân công'!$C$2:$C$259,3)="4CA")) -> #REF! | AX9: =AP9+AH9+Z9+R9 -> #REF! | AY9: =AQ9+AI9+AA9+S9 -> #REF! | AZ9: =AR9+AJ9+AB9+T9 -> #REF! | BA9: =AS9+AK9+AC9+U9 -> #REF! | BB9: =AT9+AL9+AD9+V9 -> #REF! | BC9: =AU9+AM9+AE9+W9 -> #REF! | BD9: =AV9+AN9+AF9+X9 -> #REF! | BE9: =AW9+AO9+AG9+Y9 -> #REF! | BF9: =SUMPRODUCT((B9:I9),($B$3:$I$3))*$BF$2 -> #REF! | BG9: =SUMPRODUCT(R9:Y9,$R$3:$Y$3)*$BG$2 -> #REF! | BH9: =SUMPRODUCT(Z9:AG9,$Z$3:$AG$3)*$BH$2 -> #REF! | BI9: =SUMPRODUCT(AH9:AO9,$AH$3:$AO$3)*$BI$2 -> #REF! | BJ9: =SUMPRODUCT(AP9:AW9,$AP$3:$AW$3)*$BJ$2 -> #REF! | BK9: =SUMPRODUCT((J9:Q9),($J$3:$Q$3))*$BK$2 -> #REF! | BL9: =BF9+BK9 -> #REF! | BM9: =SUM(BG9:BJ9) -> #REF! | BN9: =BM9+BK9 -> #REF! | BO9: =BL9+BM9 -> #REF!
